Workbook

Sheet SILVER
A1: Data is taken from: https://www.macrotrends.net/1470/historical-silver-prices-100-year-chart
A3: Silver Price
A4: Date | B4: Value
A5: 27395 | B5: 4.15
A6: 27396 | B6: 4.42
A7: 27397 | B7: 4.28
A8: 27398 | B8: 4.43
A9: 27399 | B9: 4.53
A10: 27400 | B10: 4.57
A11: 27401 | B11: 5
A12: 27402 | B12: 4.63
A13: 27403 | B13: 4.44
A14: 27404 | B14: 4.19
A15: 27405 | B15: 4.23
A16: 27406 | B16: 4.18
... A621: 46027 | B621: 88.36

Sheet INTEREST RATE
A1: Data is Taken From: https://fred.stlouisfed.org/series/GS10
A3: Interest Rate
A4: Date | B4: Value
A5: 27395 | B5: 7.5
A6: 27426 | B6: 7.39
A7: 27454 | B7: 7.73
A8: 27485 | B8: 8.23
A9: 27515 | B9: 8.06
A10: 27546 | B10: 7.86
A11: 27576 | B11: 8.06
A12: 27607 | B12: 8.4
A13: 27638 | B13: 8.43
A14: 27668 | B14: 8.14
A15: 27699 | B15: 8.05
A16: 27729 | B16: 8
... A620: 46113 | B620: 4.32

Sheet INFLATION RATE
A1: Data is Taken From: https://datahub.io/core/cpi-us
A3: Inflation Rate
A4: Date | B4: Inflation
A5: 27395 | B5: 0.39
A6: 27426 | B6: 0.77
A7: 27454 | B7: 0.38
A8: 27485 | B8: 0.38
A9: 27515 | B9: 0.57
A10: 27546 | B10: 0.75
A11: 27576 | B11: 1.12
A12: 27607 | B12: 0.18
A13: 27638 | B13: 0.55
A14: 27668 | B14: 0.55
A15: 27699 | B15: 0.73
A16: 27729 | B16: 0.36
... A619: 46113 | B619: 0.85

Sheet OIL 
A1: Data is Taken From: https://fred.stlouisfed.org/series/WTISPLC
A3: Oil Price
A4: Date | B4: Price
A5: 27395 | B5: 11.16
A6: 27426 | B6: 11.16
A7: 27454 | B7: 11.16
A8: 27485 | B8: 11.16
A9: 27515 | B9: 11.16
A10: 27546 | B10: 11.16
A11: 27576 | B11: 11.16
A12: 27607 | B12: 11.16
A13: 27638 | B13: 11.16
A14: 27668 | B14: 11.16
A15: 27699 | B15: 11.16
A16: 27729 | B16: 11.16
... A620: 46113 | B620: 100.32

Sheet DXY
A1: Data is Taken From: https://www.investing.com/indices/usdollar-historical-data?cid=1224074
A3: DXY
A4: Date | B4: Price
A5: 27395 | B5: 95.61
A6: 27396 | B6: 93
A7: 27397 | B7: 94.82
A8: 27398 | B8: 95.39
A9: 27399 | B9: 94.63
A10: 27400 | B10: 95.86
A11: 27401 | B11: 101.25
A12: 27402 | B12: 101.79
A13: 27403 | B13: 104.24
A14: 27404 | B14: 101.61
A15: 27405 | B15: 103.53
A16: 27406 | B16: 103.51
... A621: 46027 | B621: 99.02

Sheet GPRHT
A1: Data is taken from: https://www.matteoiacoviello.com/gpr_country.htm
A3: GRPH
A4: Date | B4: GPRHT
A5: 27395 | B5: 83.86
A6: 27426 | B6: 112.83
A7: 27454 | B7: 81.5
A8: 27485 | B8: 89.52
A9: 27515 | B9: 91.75
A10: 27546 | B10: 104.65
A11: 27576 | B11: 130.42
A12: 27607 | B12: 119.29
A13: 27638 | B13: 91.55
A14: 27668 | B14: 95.56
A15: 27699 | B15: 98.56
A16: 27729 | B16: 83.33
... A616: 45992 | B616: 142.11

Sheet SPX500
A1: Data is taken from: https://www.macrotrends.net/2324/sp-500-historical-chart-data
A3: GRPH
A4: Date | B4: Value
A5: 27395 | B5: 76.98
A6: 27426 | B6: 81.59
A7: 27454 | B7: 83.36
A8: 27485 | B8: 87.3
A9: 27515 | B9: 91.15
A10: 27546 | B10: 95.19
A11: 27576 | B11: 88.75
A12: 27607 | B12: 86.88
A13: 27638 | B13: 83.87
A14: 27668 | B14: 89.04
A15: 27699 | B15: 91.24
A16: 27729 | B16: 90.19
... A620: 46113 | B620: 7209.01

Sheet REGRESSION SILVER 1975-2024
B1: ALL DATA EXTRACTED
B3: Independent Variable:- | E3: Dependent Variable: Gold Price
B4: 1.Interest Rate
B5: 2. Inflation Rate
B6: 3. Oil Price
B7: 4. DXY
B8: 5. GPRH
C10: Y | D10: X2 | E10: X3 | F10: X6 | G10: X1 | H10: X5 | I10: X4
B11: DATE | C11: Silver Price | D11: Inflation Changes | E11: Oil Price | F11: SPX500 | G11: Interest Rate | H11: GPRHT | I11: DXY | L11: Interest Rate | M11: Inflation Changes | N11: Oil Price | O11: Oil Price | P11: GPRHT | Q11: SPX500
B12: 27395 | C12: 4.15 | D12: 0.39 | E12: 11.16 | F12: 76.98 | G12: 7.5 | H12: 83.855362 | I12: 95.61 | K12: Interest Rate | L12: 1
B13: 27426 | C13: 4.42 | D13: 0.77 | E13: 11.16 | F13: 81.59 | G13: 7.39 | H13: 112.82957 | I13: 93 | K13: Inflation Changes | L13: 0.33132365 | M13: 1
B14: 27454 | C14: 4.28 | D14: 0.38 | E14: 11.16 | F14: 83.36 | G14: 7.73 | H14: 81.504486 | I14: 94.82 | K14: Oil Price | L14: -0.57507259 | M14: -0.079022384 | N14: 1 | O14: 1
B15: 27485 | C15: 4.43 | D15: 0.38 | E15: 11.16 | F15: 87.3 | G15: 8.23 | H15: 89.517914 | I15: 95.39 | K15: DXY | L15: 0.47736574 | M15: 0.0030447475 | N15: -0.38291898 | O15: -0.38291898
B16: 27515 | C16: 4.53 | D16: 0.57 | E16: 11.16 | F16: 91.15 | G16: 8.06 | H16: 91.751518 | I16: 94.63 | K16: GPRHT | L16: 0.28471385 | M16: 0.20999041 | N16: -0.023984135 | O16: -0.023984135 | P16: 1
B17: 27546 | C17: 4.57 | D17: 0.75 | E17: 11.16 | F17: 95.19 | G17: 7.86 | H17: 104.65205 | I17: 95.86 | K17: SPX500 | L17: -0.67758122 | M17: -0.14469664 | N17: 0.60290619 | O17: 0.60290619 | P17: -0.0062193239 | Q17: 1
B18: 27576 | C18: 5 | D18: 1.12 | E18: 11.16 | F18: 88.75 | G18: 8.06 | H18: 130.41939 | I18: 101.25
B19: 27607 | C19: 4.63 | D19: 0.18 | E19: 11.16 | F19: 86.88 | G19: 8.4 | H19: 119.28921 | I19: 101.79 | K19: SUMMARY OUTPUT
B20: 27638 | C20: 4.44 | D20: 0.55 | E20: 11.16 | F20: 83.87 | G20: 8.43 | H20: 91.548004 | I20: 104.24
B21: 27668 | C21: 4.19 | D21: 0.55 | E21: 11.16 | F21: 89.04 | G21: 8.14 | H21: 95.561226 | I21: 101.61 | K21: Regression Statistics
B22: 27699 | C22: 4.23 | D22: 0.73 | E22: 11.16 | F22: 91.24 | G22: 8.05 | H22: 98.560883 | I22: 103.53 | K22: Multiple R | L22: 0.83473601
B23: 27729 | C23: 4.18 | D23: 0.36 | E23: 11.16 | F23: 90.19 | G23: 8 | H23: 83.333817 | I23: 103.51 | K23: R Square | L23: 0.69678421
B24: 27760 | C24: 4.01 | D24: 0.18 | E24: 11.16 | F24: 100.86 | G24: 7.74 | H24: 99.605568 | I24: 103.88 | K24: Adjusted R Square | L24: 0.69371626
B25: 27791 | C25: 4.16 | D25: 0.36 | E25: 12.03 | F25: 99.71 | G25: 7.79 | H25: 61.639027 | I25: 103.66 | K25: Standard Error | L25: 4.6720332
B26: 27820 | C26: 4.11 | D26: 0.18 | E26: 12.1 | F26: 102.77 | G26: 7.73 | H26: 94.420204 | I26: 105.34 | K26: Observations | L26: 600
B27: 27851 | C27: 4.43 | D27: 0.36 | E27: 12.17 | F27: 101.64 | G27: 7.56 | H27: 76.181549 | I27: 106.23
B28: 27881 | C28: 4.62 | D28: 0.71 | E28: 12.17 | F28: 100.18 | G28: 7.9 | H28: 90.447502 | I28: 107.29 | K28: ANOVA
B29: 27912 | C29: 4.83 | D29: 0.53 | E29: 12.17 | F29: 104.28 | G29: 7.86 | H29: 79.715508 | I29: 106.64 | L29: df | M29: SS | N29: MS | O29: F | P29: Significance F
B30: 27942 | C30: 4.54 | D30: 0.53 | E30: 12.17 | F30: 103.44 | G30: 7.83 | H30: 62.278923 | I30: 106.56 | K30: Regression | L30: 6 | M30: 29744.935 | N30: 4957.4891 | O30: 227.11715 | P30: 4.7236857e-150
B31: 27973 | C31: 4.11 | D31: 0.53 | E31: 12.17 | F31: 102.91 | G31: 7.77 | H31: 108.76436 | I31: 106.13 | K31: Residual | L31: 593 | M31: 12943.941 | N31: 21.827894
B32: 28004 | C32: 4.39 | D32: 0.35 | E32: 13.9 | F32: 105.24 | G32: 7.59 | H32: 76.601311 | I32: 105.5 | K32: Total | L32: 599 | M32: 42688.876
B33: 28034 | C33: 4.27 | D33: 0.52 | E33: 13.9 | F33: 102.9 | G33: 7.41 | H33: 85.47039 | I33: 105.94
B34: 28065 | C34: 4.28 | D34: 0.17 | E34: 13.9 | F34: 102.1 | G34: 7.29 | H34: 66.941399 | I34: 106.19 | L34: Coefficients | M34: Standard Error | N34: t Stat | O34: P-value | P34: Lower 95% | Q34: Upper 95% | R34: Lower 95.0% | S34: Upper 95.0%
B35: 28095 | C35: 4.36 | D35: 0.34 | E35: 13.9 | F35: 107.46 | G35: 6.87 | H35: 80.23188 | I35: 104.56 | K35: Intercept | L35: 3.6636286 | M35: 1.6207602 | N35: 2.2604383 | O35: 0.024155833 | P35: 0.48050007 | Q35: 6.8467571 | R35: 0.48050007 | S35: 6.8467571
B36: 28126 | C36: 4.45 | D36: 0.52 | E36: 13.9 | F36: 102.03 | G36: 7.21 | H36: 78.585274 | I36: 105.54 | K36: Interest Rate | L36: 0.21193204 | M36: 0.11115382 | N36: 1.9066555 | O36: 0.057048241 | P36: -0.0063709991 | Q36: 0.43023507 | R36: -0.0063709991 | S36: 0.43023507
B37: 28157 | C37: 4.73 | D37: 1.03 | E37: 13.9 | F37: 99.82 | G37: 7.39 | H37: 84.99382 | I37: 105.26 | K37: Inflation Changes | L37: 1.6351952 | M37: 0.57601186 | N37: 2.838822 | O37: 0.0046831576 | P37: 0.50392371 | Q37: 2.7664666 | R37: 0.50392371 | S37: 2.7664666
B38: 28185 | C38: 4.83 | D38: 0.68 | E38: 13.9 | F38: 98.42 | G38: 7.46 | H38: 83.106659 | I38: 105.03 | K38: Oil Price | L38: 0.19115369 | M38: 0.0093749735 | N38: 20.389784 | O38: 1.9788878e-70 | P38: 0.1727415 | Q38: 0.20956588 | R38: 0.1727415 | S38: 0.20956588
B39: 28216 | C39: 4.71 | D39: 0.84 | E39: 13.9 | F39: 98.44 | G39: 7.37 | H39: 94.549332 | I39: 104.39 | K39: DXY | L39: -0.046555369 | M39: 0.017560694 | N39: -2.6511121 | O39: 0.0082370937 | P39: -0.08104409 | Q39: -0.012066649 | R39: -0.08104409 | S39: -0.012066649
B40: 28246 | C40: 4.56 | D40: 0.5 | E40: 13.9 | F40: 96.12 | G40: 7.46 | H40: 94.379166 | I40: 104.52 | K40: GPRHT | L40: 0.00086295447 | M40: 0.0058019103 | N40: 0.14873626 | O40: 0.88181231 | P40: -0.010531838 | Q40: 0.012257747 | R40: -0.010531838 | S40: 0.012257747
B41: 28277 | C41: 4.51 | D41: 0.66 | E41: 13.9 | F41: 100.48 | G41: 7.28 | H41: 84.294769 | I41: 103.84 | K41: SPX500 | L41: 0.0020846991 | M41: 0.00025373393 | N41: 8.2160833 | O41: 1.3241921e-15 | P41: 0.0015863726 | Q41: 0.0025830256 | R41: 0.0015863726 | S41: 0.0025830256
B42: 28307 | C42: 4.52 | D42: 0.49 | E42: 13.9 | F42: 98.85 | G42: 7.33 | H42: 98.000565 | I42: 102.86
...

Sheet CHART SILVER 1975-2024
