Workbook

Sheet GOLD
A1: Data is taken from: https://www.macrotrends.net/1333/historical-gold-prices-100-year-chart
A3: Gold Price
A4: Date | B4: Price
A5: 27395 | B5: 176.25
A6: 27396 | B6: 181.75
A7: 27397 | B7: 177.75
A8: 27398 | B8: 167.4
A9: 27399 | B9: 167.75
A10: 27400 | B10: 166
A11: 27401 | B11: 166.4
A12: 27402 | B12: 161.5
A13: 27403 | B13: 138.25
A14: 27404 | B14: 143.4
A15: 27405 | B15: 138.25
A16: 27406 | B16: 140.25
... A620: 46026 | B620: 4629.5648

Sheet SILVER
A1: Data is taken from: https://www.macrotrends.net/1470/historical-silver-prices-100-year-chart
A3: Silver Price
A4: Date | B4: Value
A5: 27395 | B5: 4.15
A6: 27396 | B6: 4.42
A7: 27397 | B7: 4.28
A8: 27398 | B8: 4.43
A9: 27399 | B9: 4.53
A10: 27400 | B10: 4.57
A11: 27401 | B11: 5
A12: 27402 | B12: 4.63
A13: 27403 | B13: 4.44
A14: 27404 | B14: 4.19
A15: 27405 | B15: 4.23
A16: 27406 | B16: 4.18
... A621: 46027 | B621: 88.36

Sheet INTEREST RATE
A1: Data is Taken From: https://fred.stlouisfed.org/series/GS10
A3: Interest Rate
A4: Date | B4: Value
A5: 27395 | B5: 7.5
A6: 27426 | B6: 7.39
A7: 27454 | B7: 7.73
A8: 27485 | B8: 8.23
A9: 27515 | B9: 8.06
A10: 27546 | B10: 7.86
A11: 27576 | B11: 8.06
A12: 27607 | B12: 8.4
A13: 27638 | B13: 8.43
A14: 27668 | B14: 8.14
A15: 27699 | B15: 8.05
A16: 27729 | B16: 8
... A620: 46113 | B620: 4.32

Sheet INFLATION RATE
A1: Data is Taken From: https://datahub.io/core/cpi-us
A3: Inflation Rate
A4: Date | B4: Inflation
A5: 27395 | B5: 0.39
A6: 27426 | B6: 0.77
A7: 27454 | B7: 0.38
A8: 27485 | B8: 0.38
A9: 27515 | B9: 0.57
A10: 27546 | B10: 0.75
A11: 27576 | B11: 1.12
A12: 27607 | B12: 0.18
A13: 27638 | B13: 0.55
A14: 27668 | B14: 0.55
A15: 27699 | B15: 0.73
A16: 27729 | B16: 0.36
... A619: 46113 | B619: 0.85

Sheet OIL 
A1: Data is Taken From: https://fred.stlouisfed.org/series/WTISPLC
A3: Oil Price
A4: Date | B4: Price
A5: 27395 | B5: 11.16
A6: 27426 | B6: 11.16
A7: 27454 | B7: 11.16
A8: 27485 | B8: 11.16
A9: 27515 | B9: 11.16
A10: 27546 | B10: 11.16
A11: 27576 | B11: 11.16
A12: 27607 | B12: 11.16
A13: 27638 | B13: 11.16
A14: 27668 | B14: 11.16
A15: 27699 | B15: 11.16
A16: 27729 | B16: 11.16
... A620: 46113 | B620: 100.32

Sheet DXY
A1: Data is Taken From: https://www.investing.com/indices/usdollar-historical-data?cid=1224074
A3: DXY
A4: Date | B4: Price
A5: 27395 | B5: 95.61
A6: 27396 | B6: 93
A7: 27397 | B7: 94.82
A8: 27398 | B8: 95.39
A9: 27399 | B9: 94.63
A10: 27400 | B10: 95.86
A11: 27401 | B11: 101.25
A12: 27402 | B12: 101.79
A13: 27403 | B13: 104.24
A14: 27404 | B14: 101.61
A15: 27405 | B15: 103.53
A16: 27406 | B16: 103.51
... A621: 46027 | B621: 99.02

Sheet GPRHT
A1: Data is taken from: https://www.matteoiacoviello.com/gpr_country.htm
A3: GRPH
A4: Date | B4: GPRHT
A5: 27395 | B5: 83.86
A6: 27426 | B6: 112.83
A7: 27454 | B7: 81.5
A8: 27485 | B8: 89.52
A9: 27515 | B9: 91.75
A10: 27546 | B10: 104.65
A11: 27576 | B11: 130.42
A12: 27607 | B12: 119.29
A13: 27638 | B13: 91.55
A14: 27668 | B14: 95.56
A15: 27699 | B15: 98.56
A16: 27729 | B16: 83.33
... A616: 45992 | B616: 142.11

Sheet SPX500
A1: Data is taken from: https://www.macrotrends.net/2324/sp-500-historical-chart-data
A3: GRPH
A4: Date | B4: Value
A5: 27395 | B5: 76.98
A6: 27426 | B6: 81.59
A7: 27454 | B7: 83.36
A8: 27485 | B8: 87.3
A9: 27515 | B9: 91.15
A10: 27546 | B10: 95.19
A11: 27576 | B11: 88.75
A12: 27607 | B12: 86.88
A13: 27638 | B13: 83.87
A14: 27668 | B14: 89.04
A15: 27699 | B15: 91.24
A16: 27729 | B16: 90.19
... A620: 46113 | B620: 7209.01

Sheet REGRESSION GOLD 
B1: ALL DATA EXTRACTED
B3: Independent Variable:- | E3: Dependent Variable: Gold Price
B4: 1.Interest Rate
B5: 2. Inflation Rate
B6: 3. Oil Price
B7: 4. DXY
B8: 5. GPRH
C10: Y | D10: X1 | E10: X2 | F10: X3 | G10: X4 | H10: X5 | I10: X6
B11: DATE | C11: Gold price | D11: Interest Rate | E11: Inflation Changes | F11: Oil Price | G11: DXY | H11: GPRHT | I11: SPX500 | L11: Interest Rate | M11: Inflation Changes | N11: Oil Price | O11: DXY | P11: GPRHT | Q11: SPX500
B12: 27395 | C12: 176.25 | D12: 7.5 | E12: 0.39 | F12: 11.16 | G12: 95.61 | H12: 83.855362 | I12: 76.98 | K12: Interest Rate | L12: 1
B13: 27426 | C13: 181.75 | D13: 7.39 | E13: 0.77 | F13: 11.16 | G13: 93 | H13: 112.82957 | I13: 81.59 | K13: Inflation Changes | L13: 0.33186373 | M13: 1
B14: 27454 | C14: 177.75 | D14: 7.73 | E14: 0.38 | F14: 11.16 | G14: 94.82 | H14: 81.504486 | I14: 83.36 | K14: Oil Price | L14: -0.57753328 | M14: -0.079975981 | N14: 1
B15: 27485 | C15: 167.4 | D15: 8.23 | E15: 0.38 | F15: 11.16 | G15: 95.39 | H15: 89.517914 | I15: 87.3 | K15: DXY | L15: 0.47283863 | M15: 0.0034507835 | N15: -0.37456919 | O15: 1
B16: 27515 | C16: 167.75 | D16: 8.06 | E16: 0.57 | F16: 11.16 | G16: 94.63 | H16: 91.751518 | I16: 91.15 | K16: GPRHT | L16: 0.26201117 | M16: 0.19700818 | N16: -0.0015869465 | O16: 0.16835579 | P16: 1
B17: 27546 | C17: 166 | D17: 7.86 | E17: 0.75 | F17: 11.16 | G17: 95.86 | H17: 104.65205 | I17: 95.19 | K17: SPX500 | L17: -0.62386929 | M17: -0.14306449 | N17: 0.57694065 | O17: -0.058942449 | P17: 0.090846169 | Q17: 1
B18: 27576 | C18: 166.4 | D18: 8.06 | E18: 1.12 | F18: 11.16 | G18: 101.25 | H18: 130.41939 | I18: 88.75
B19: 27607 | C19: 161.5 | D19: 8.4 | E19: 0.18 | F19: 11.16 | G19: 101.79 | H19: 119.28921 | I19: 86.88 | K19: SUMMARY OUTPUT
B20: 27638 | C20: 138.25 | D20: 8.43 | E20: 0.55 | F20: 11.16 | G20: 104.24 | H20: 91.548004 | I20: 83.87
B21: 27668 | C21: 143.4 | D21: 8.14 | E21: 0.55 | F21: 11.16 | G21: 101.61 | H21: 95.561226 | I21: 89.04 | K21: Regression Statistics
B22: 27699 | C22: 138.25 | D22: 8.05 | E22: 0.73 | F22: 11.16 | G22: 103.53 | H22: 98.560883 | I22: 91.24 | K22: Multiple R | L22: 0.93383511
B23: 27729 | C23: 140.25 | D23: 8 | E23: 0.36 | F23: 11.16 | G23: 103.51 | H23: 83.333817 | I23: 90.19 | K23: R Square | L23: 0.87204802
B24: 27760 | C24: 128 | D24: 7.74 | E24: 0.18 | F24: 11.16 | G24: 103.88 | H24: 99.605568 | I24: 100.86 | K24: Adjusted R Square | L24: 0.87077907
B25: 27791 | C25: 132.3 | D25: 7.79 | E25: 0.36 | F25: 12.03 | G25: 103.66 | H25: 61.639027 | I25: 99.71 | K25: Standard Error | L25: 249.17476
B26: 27820 | C26: 129.5 | D26: 7.73 | E26: 0.18 | F26: 12.1 | G26: 105.34 | H26: 94.420204 | I26: 102.77 | K26: Observations | L26: 612
B27: 27851 | C27: 128.15 | D27: 7.56 | E27: 0.36 | F27: 12.17 | G27: 106.23 | H27: 76.181549 | I27: 101.64
B28: 27881 | C28: 125.25 | D28: 7.9 | E28: 0.71 | F28: 12.17 | G28: 107.29 | H28: 90.447502 | I28: 100.18 | K28: ANOVA
B29: 27912 | C29: 123.8 | D29: 7.86 | E29: 0.53 | F29: 12.17 | G29: 106.64 | H29: 79.715508 | I29: 104.28 | L29: df | M29: SS | N29: MS | O29: F | P29: Significance F
B30: 27942 | C30: 112.4 | D30: 7.83 | E30: 0.53 | F30: 12.17 | G30: 106.56 | H30: 62.278923 | I30: 103.44 | K30: Regression | L30: 6 | M30: 2.5600996e+08 | N30: 42668326 | O30: 687.2227 | P30: 2.6788082e-266 | Q30: <5%
B31: 27973 | C31: 103.05 | D31: 7.77 | E31: 0.53 | F31: 12.17 | G31: 106.13 | H31: 108.76436 | I31: 102.91 | K31: Residual | L31: 605 | M31: 37563278 | N31: 62088.062
B32: 28004 | C32: 116.1 | D32: 7.59 | E32: 0.35 | F32: 13.9 | G32: 105.5 | H32: 76.601311 | I32: 105.24 | K32: Total | L32: 611 | M32: 2.9357323e+08
B33: 28034 | C33: 122.3 | D33: 7.41 | E33: 0.52 | F33: 13.9 | G33: 105.94 | H33: 85.47039 | I33: 102.9
B34: 28065 | C34: 130.1 | D34: 7.29 | E34: 0.17 | F34: 13.9 | G34: 106.19 | H34: 66.941399 | I34: 102.1 | L34: Coefficients | M34: Standard Error | N34: t Stat | O34: P-value | P34: Lower 95% | Q34: Upper 95% | R34: Lower 95.0% | S34: Upper 95.0%
B35: 28095 | C35: 134.55 | D35: 6.87 | E35: 0.34 | F35: 13.9 | G35: 104.56 | H35: 80.23188 | I35: 107.46 | K35: Intercept | L35: 242.60182 | M35: 86.223714 | N35: 2.8136322 | O35: 0.0050577059 | P35: 73.267687 | Q35: 411.93595 | R35: 73.267687 | S35: 411.93595
B36: 28126 | C36: 132.1 | D36: 7.21 | E36: 0.52 | F36: 13.9 | G36: 105.54 | H36: 78.585274 | I36: 102.03 | K36: Interest Rate | L36: 26.723719 | M36: 5.6013533 | N36: 4.7709397 | O36: 2.3010327e-06 | P36: 15.723262 | Q36: 37.724176 | R36: 15.723262 | S36: 37.724176
B37: 28157 | C37: 142.25 | D37: 7.39 | E37: 1.03 | F37: 13.9 | G37: 105.26 | H37: 84.99382 | I37: 99.82 | K37: Inflation Changes | L37: -94.522587 | M37: 30.401956 | N37: -3.1090955 | O37: 0.0019647796 | P37: -154.22877 | Q37: -34.816403 | R37: -154.22877 | S37: -34.816403
B38: 28185 | C38: 149.8 | D38: 7.46 | E38: 0.68 | F38: 13.9 | G38: 105.03 | H38: 83.106659 | I38: 98.42 | K38: Oil Price | L38: 6.3812518 | M38: 0.49018784 | N38: 13.017972 | O38: 2.4879325e-34 | P38: 5.4185754 | Q38: 7.3439282 | R38: 5.4185754 | S38: 7.3439282
B39: 28216 | C39: 146.5 | D39: 7.37 | E39: 0.84 | F39: 13.9 | G39: 104.39 | H39: 94.549332 | I39: 98.44 | K39: DXY | L39: -5.0019119 | M39: 0.91241593 | N39: -5.4820524 | O39: 6.1798541e-08 | P39: -6.793799 | Q39: -3.2100248 | R39: -6.793799 | S39: -3.2100248
B40: 28246 | C40: 143.2 | D40: 7.46 | E40: 0.5 | F40: 13.9 | G40: 104.52 | H40: 94.379166 | I40: 96.12 | K40: GPRHT | L40: 1.0702037 | M40: 0.30553353 | N40: 3.5027372 | O40: 0.00049447121 | P40: 0.47016857 | Q40: 1.6702388 | R40: 0.47016857 | S40: 1.6702388
B41: 28277 | C41: 142.95 | D41: 7.28 | E41: 0.66 | F41: 13.9 | G41: 103.84 | H41: 84.294769 | I41: 100.48 | K41: SPX500 | L41: 0.39140727 | M41: 0.011032062 | N41: 35.479069 | O41: 6.0741615e-150 | P41: 0.36974149 | Q41: 0.41307306 | R41: 0.36974149 | S41: 0.41307306
B42: 28307 | C42: 144.5 | D42: 7.33 | E42: 0.49 | F42: 13.9 | G42: 102.86 | H42: 98.000565 | I42: 98.85 | O42: P-value <5%
...

Sheet REGRESSION GOLD  (2)
B1: ALL DATA EXTRACTED
B3: Independent Variable:-
B4: 1.Interest Rate
B5: 2. Inflation Rate
B6: 3. Oil Price
B7: 4. DXY
B8: 5. GPRH
C10: Y | D10: X1 | E10: X2 | F10: X3 | G10: X4 | H10: X5
B11: DATE | C11: Gold price | D11: Interest Rate | E11: Oil Price | F11: DXY | G11: GPRHT | H11: SPX500 | K11: Interest Rate | L11: Oil Price | M11: DXY | N11: GPRHT | O11: SPX500
B12: 27395 | C12: 176.25 | D12: 7.5 | E12: 11.16 | F12: 95.61 | G12: 83.855362 | H12: 76.98 | J12: Interest Rate | K12: 1
B13: 27426 | C13: 181.75 | D13: 7.39 | E13: 11.16 | F13: 93 | G13: 112.82957 | H13: 81.59 | J13: Oil Price | K13: -0.57753328 | L13: 1
B14: 27454 | C14: 177.75 | D14: 7.73 | E14: 11.16 | F14: 94.82 | G14: 81.504486 | H14: 83.36 | J14: DXY | K14: 0.47283863 | L14: -0.37456919 | M14: 1
B15: 27485 | C15: 167.4 | D15: 8.23 | E15: 11.16 | F15: 95.39 | G15: 89.517914 | H15: 87.3 | J15: GPRHT | K15: 0.26201117 | L15: -0.0015869465 | M15: 0.16835579 | N15: 1
B16: 27515 | C16: 167.75 | D16: 8.06 | E16: 11.16 | F16: 94.63 | G16: 91.751518 | H16: 91.15 | J16: SPX500 | K16: -0.62386929 | L16: 0.57694065 | M16: -0.058942449 | N16: 0.090846169 | O16: 1
B17: 27546 | C17: 166 | D17: 7.86 | E17: 11.16 | F17: 95.86 | G17: 104.65205 | H17: 95.19
B18: 27576 | C18: 166.4 | D18: 8.06 | E18: 11.16 | F18: 101.25 | G18: 130.41939 | H18: 88.75 | J18: SUMMARY OUTPUT
B19: 27607 | C19: 161.5 | D19: 8.4 | E19: 11.16 | F19: 101.79 | G19: 119.28921 | H19: 86.88
B20: 27638 | C20: 138.25 | D20: 8.43 | E20: 11.16 | F20: 104.24 | G20: 91.548004 | H20: 83.87 | J20: Regression Statistics
B21: 27668 | C21: 143.4 | D21: 8.14 | E21: 11.16 | F21: 101.61 | G21: 95.561226 | H21: 89.04 | J21: Multiple R | K21: 0.93273986
B22: 27699 | C22: 138.25 | D22: 8.05 | E22: 11.16 | F22: 103.53 | G22: 98.560883 | H22: 91.24 | J22: R Square | K22: 0.87000364
B23: 27729 | C23: 140.25 | D23: 8 | E23: 11.16 | F23: 103.51 | G23: 83.333817 | H23: 90.19 | J23: Adjusted R Square | K23: 0.86893107
B24: 27760 | C24: 128 | D24: 7.74 | E24: 11.16 | F24: 103.88 | G24: 99.605568 | H24: 100.86 | J24: Standard Error | K24: 250.95018
B25: 27791 | C25: 132.3 | D25: 7.79 | E25: 12.03 | F25: 103.66 | G25: 61.639027 | H25: 99.71 | J25: Observations | K25: 612
B26: 27820 | C26: 129.5 | D26: 7.73 | E26: 12.1 | F26: 105.34 | G26: 94.420204 | H26: 102.77
B27: 27851 | C27: 128.15 | D27: 7.56 | E27: 12.17 | F27: 106.23 | G27: 76.181549 | H27: 101.64 | J27: ANOVA
B28: 27881 | C28: 125.25 | D28: 7.9 | E28: 12.17 | F28: 107.29 | G28: 90.447502 | H28: 100.18 | K28: df | L28: SS | M28: MS | N28: F | O28: Significance F
B29: 27912 | C29: 123.8 | D29: 7.86 | E29: 12.17 | F29: 106.64 | G29: 79.715508 | H29: 104.28 | J29: Regression | K29: 5 | L29: 2.5540978e+08 | M29: 51081957 | N29: 811.13383 | O29: 1.07636e-265
B30: 27942 | C30: 112.4 | D30: 7.83 | E30: 12.17 | F30: 106.56 | G30: 62.278923 | H30: 103.44 | J30: Residual | K30: 606 | L30: 38163450 | M30: 62975.991
B31: 27973 | C31: 103.05 | D31: 7.77 | E31: 12.17 | F31: 106.13 | G31: 108.76436 | H31: 102.91 | J31: Total | K31: 611 | L31: 2.9357323e+08
B32: 28004 | C32: 116.1 | D32: 7.59 | E32: 13.9 | F32: 105.5 | G32: 76.601311 | H32: 105.24
B33: 28034 | C33: 122.3 | D33: 7.41 | E33: 13.9 | F33: 105.94 | G33: 85.47039 | H33: 102.9 | K33: Coefficients | L33: Standard Error | M33: t Stat | N33: P-value | O33: Lower 95% | P33: Upper 95% | Q33: Lower 95.0% | R33: Upper 95.0% | T33: EQUATION
B34: 28065 | C34: 130.1 | D34: 7.29 | E34: 13.9 | F34: 106.19 | G34: 66.941399 | H34: 102.1 | J34: Intercept | K34: 209.45035 | L34: 86.17152 | M34: 2.4306215 | N34: 0.015362055 | O34: 40.219279 | P34: 378.68142 | Q34: 40.219279 | R34: 378.68142 | T34: Y = 209.45 + 20.89(X1) + 6.39(X2) -4.43 (X3) +0.99 (X4) + 0.39(X5)
B35: 28095 | C35: 134.55 | D35: 6.87 | E35: 13.9 | F35: 104.56 | G35: 80.23188 | H35: 107.46 | J35: Interest Rate | K35: 20.886339 | L35: 5.3149201 | M35: 3.929756 | N35: 9.4830148e-05 | O35: 10.44844 | P35: 31.324238 | Q35: 10.44844 | R35: 31.324238
B36: 28126 | C36: 132.1 | D36: 7.21 | E36: 13.9 | F36: 105.54 | G36: 78.585274 | H36: 102.03 | J36: Oil Price | K36: 6.2967822 | L36: 0.49292166 | M36: 12.774408 | N36: 2.9266632e-33 | O36: 5.3287401 | P36: 7.2648243 | Q36: 5.3287401 | R36: 7.2648243
B37: 28157 | C37: 142.25 | D37: 7.39 | E37: 13.9 | F37: 105.26 | G37: 84.99382 | H37: 99.82 | J37: DXY | K37: -4.4341527 | L37: 0.9003246 | M37: -4.9250601 | N37: 1.08912e-06 | O37: -6.2022879 | P37: -2.6660176 | Q37: -6.2022879 | R37: -2.6660176
B38: 28185 | C38: 149.8 | D38: 7.46 | E38: 13.9 | F38: 105.03 | G38: 83.106659 | H38: 98.42 | J38: GPRHT | K38: 0.99423825 | L38: 0.30672502 | M38: 3.2414645 | N38: 0.0012543903 | O38: 0.39186519 | P38: 1.5966113 | Q38: 0.39186519 | R38: 1.5966113
B39: 28216 | C39: 146.5 | D39: 7.37 | E39: 13.9 | F39: 104.39 | G39: 94.549332 | H39: 98.44 | J39: SPX500 | K39: 0.38811174 | L39: 0.011059264 | M39: 35.093812 | N39: 4.1683744e-148 | O39: 0.3663926 | P39: 0.40983088 | Q39: 0.3663926 | R39: 0.40983088
B40: 28246 | C40: 143.2 | D40: 7.46 | E40: 13.9 | F40: 104.52 | G40: 94.379166 | H40: 96.12
B41: 28277 | C41: 142.95 | D41: 7.28 | E41: 13.9 | F41: 103.84 | G41: 84.294769 | H41: 100.48
B42: 28307 | C42: 144.5 | D42: 7.33 | E42: 13.9 | F42: 102.86 | G42: 98.000565 | H42: 98.85
...

Sheet REGRESSION GOLD 1975-2024
B1: ALL DATA EXTRACTED
B3: Independent Variable:- | D3: Dependent Variable: Gold Price
B4: 1.Interest Rate
B5: 2. Inflation Rate
B6: 3. Oil Price
B7: 4. DXY
B8: 5. GPRH
C10: Y | D10: X3 | E10: X4 | F10: X5 | G10: X6 | H10: X1 | I10: X2
B11: DATE | C11: Gold price | D11: Oil Price | E11: DXY | F11: GPRHT | G11: SPX500 | H11: Interest Rate | I11: Inflation Changes | L11: Interest Rate | M11: Inflation Changes | N11: Oil Price | O11: Oil Price | P11: GPRHT | Q11: SPX500
B12: 27395 | C12: 176.25 | D12: 11.16 | E12: 95.61 | F12: 83.855362 | G12: 76.98 | H12: 7.5 | I12: 0.39 | K12: Interest Rate | L12: 1
B13: 27426 | C13: 181.75 | D13: 11.16 | E13: 93 | F13: 112.82957 | G13: 81.59 | H13: 7.39 | I13: 0.77 | K13: Inflation Changes | L13: 0.33132365 | M13: 1
B14: 27454 | C14: 177.75 | D14: 11.16 | E14: 94.82 | F14: 81.504486 | G14: 83.36 | H14: 7.73 | I14: 0.38 | K14: Oil Price | L14: -0.57507259 | M14: -0.079022384 | N14: 1 | O14: 1
B15: 27485 | C15: 167.4 | D15: 11.16 | E15: 95.39 | F15: 89.517914 | G15: 87.3 | H15: 8.23 | I15: 0.38 | K15: DXY | L15: 0.47736574 | M15: 0.0030447475 | N15: -0.38291898 | O15: -0.38291898
B16: 27515 | C16: 167.75 | D16: 11.16 | E16: 94.63 | F16: 91.751518 | G16: 91.15 | H16: 8.06 | I16: 0.57 | K16: GPRHT | L16: 0.28471385 | M16: 0.20999041 | N16: -0.023984135 | O16: -0.023984135 | P16: 1
B17: 27546 | C17: 166 | D17: 11.16 | E17: 95.86 | F17: 104.65205 | G17: 95.19 | H17: 7.86 | I17: 0.75 | K17: SPX500 | L17: -0.67758122 | M17: -0.14469664 | N17: 0.60290619 | O17: 0.60290619 | P17: -0.0062193239 | Q17: 1
B18: 27576 | C18: 166.4 | D18: 11.16 | E18: 101.25 | F18: 130.41939 | G18: 88.75 | H18: 8.06 | I18: 1.12
B19: 27607 | C19: 161.5 | D19: 11.16 | E19: 101.79 | F19: 119.28921 | G19: 86.88 | H19: 8.4 | I19: 0.18 | K19: SUMMARY OUTPUT
B20: 27638 | C20: 138.25 | D20: 11.16 | E20: 104.24 | F20: 91.548004 | G20: 83.87 | H20: 8.43 | I20: 0.55
B21: 27668 | C21: 143.4 | D21: 11.16 | E21: 101.61 | F21: 95.561226 | G21: 89.04 | H21: 8.14 | I21: 0.55 | K21: Regression Statistics
B22: 27699 | C22: 138.25 | D22: 11.16 | E22: 103.53 | F22: 98.560883 | G22: 91.24 | H22: 8.05 | I22: 0.73 | K22: Multiple R | L22: 0.92675731
B23: 27729 | C23: 140.25 | D23: 11.16 | E23: 103.51 | F23: 83.333817 | G23: 90.19 | H23: 8 | I23: 0.36 | K23: R Square | L23: 0.85887911
B24: 27760 | C24: 128 | D24: 11.16 | E24: 103.88 | F24: 99.605568 | G24: 100.86 | H24: 7.74 | I24: 0.18 | K24: Adjusted R Square | L24: 0.85745125
B25: 27791 | C25: 132.3 | D25: 12.03 | E25: 103.66 | F25: 61.639027 | G25: 99.71 | H25: 7.79 | I25: 0.36 | K25: Standard Error | L25: 219.82366
B26: 27820 | C26: 129.5 | D26: 12.1 | E26: 105.34 | F26: 94.420204 | G26: 102.77 | H26: 7.73 | I26: 0.18 | K26: Observations | L26: 600
B27: 27851 | C27: 128.15 | D27: 12.17 | E27: 106.23 | F27: 76.181549 | G27: 101.64 | H27: 7.56 | I27: 0.36
B28: 27881 | C28: 125.25 | D28: 12.17 | E28: 107.29 | F28: 90.447502 | G28: 100.18 | H28: 7.9 | I28: 0.71 | K28: ANOVA
B29: 27912 | C29: 123.8 | D29: 12.17 | E29: 106.64 | F29: 79.715508 | G29: 104.28 | H29: 7.86 | I29: 0.53 | L29: df | M29: SS | N29: MS | O29: F | P29: Significance F
B30: 27942 | C30: 112.4 | D30: 12.17 | E30: 106.56 | F30: 62.278923 | G30: 103.44 | H30: 7.83 | I30: 0.53 | K30: Regression | L30: 6 | M30: 1.7439913e+08 | N30: 29066522 | O30: 601.51185 | P30: 2.3418762e-248
B31: 27973 | C31: 103.05 | D31: 12.17 | E31: 106.13 | F31: 108.76436 | G31: 102.91 | H31: 7.77 | I31: 0.53 | K31: Residual | L31: 593 | M31: 28655209 | N31: 48322.443
B32: 28004 | C32: 116.1 | D32: 13.9 | E32: 105.5 | F32: 76.601311 | G32: 105.24 | H32: 7.59 | I32: 0.35 | K32: Total | L32: 599 | M32: 2.0305434e+08
B33: 28034 | C33: 122.3 | D33: 13.9 | E33: 105.94 | F33: 85.47039 | G33: 102.9 | H33: 7.41 | I33: 0.52
B34: 28065 | C34: 130.1 | D34: 13.9 | E34: 106.19 | F34: 66.941399 | G34: 102.1 | H34: 7.29 | I34: 0.17 | L34: Coefficients | M34: Standard Error | N34: t Stat | O34: P-value | P34: Lower 95% | Q34: Upper 95% | R34: Lower 95.0% | S34: Upper 95.0%
B35: 28095 | C35: 134.55 | D35: 13.9 | E35: 104.56 | F35: 80.23188 | G35: 107.46 | H35: 6.87 | I35: 0.34 | K35: Intercept | L35: 188.57556 | M35: 76.258331 | N35: 2.4728519 | O35: 0.013683229 | P35: 38.806294 | Q35: 338.34482 | R35: 38.806294 | S35: 338.34482
B36: 28126 | C36: 132.1 | D36: 13.9 | E36: 105.54 | F36: 78.585274 | G36: 102.03 | H36: 7.21 | I36: 0.52 | K36: Interest Rate | L36: 4.5982014 | M36: 5.2298941 | N36: 0.879215 | O36: 0.37964084 | P36: -5.6731668 | Q36: 14.86957 | R36: -5.6731668 | S36: 14.86957
B37: 28157 | C37: 142.25 | D37: 13.9 | E37: 105.26 | F37: 84.99382 | G37: 99.82 | H37: 7.39 | I37: 1.03 | K37: Inflation Changes | L37: -46.390058 | M37: 27.101913 | N37: -1.7116894 | O37: 0.087476788 | P37: -99.61747 | Q37: 6.837353 | R37: -99.61747 | S37: 6.837353
B38: 28185 | C38: 149.8 | D38: 13.9 | E38: 105.03 | F38: 83.106659 | G38: 98.42 | H38: 7.46 | I38: 0.68 | K38: Oil Price | L38: 7.526549 | M38: 0.44110154 | N38: 17.063076 | O38: 2.0938337e-53 | P38: 6.6602377 | Q38: 8.3928603 | R38: 6.6602377 | S38: 8.3928603
B39: 28216 | C39: 146.5 | D39: 13.9 | E39: 104.39 | F39: 94.549332 | G39: 98.44 | H39: 7.37 | I39: 0.84 | K39: DXY | L39: -2.5525587 | M39: 0.82624758 | N39: -3.0893388 | O39: 0.0020999463 | P39: -4.1752862 | Q39: -0.92983118 | R39: -4.1752862 | S39: -0.92983118
B40: 28246 | C40: 143.2 | D40: 13.9 | E40: 104.52 | F40: 94.379166 | G40: 96.12 | H40: 7.46 | I40: 0.5 | K40: GPRHT | L40: 0.89844929 | M40: 0.27298547 | N40: 3.2911982 | O40: 0.0010568568 | P40: 0.36231333 | Q40: 1.4345852 | R40: 0.36231333 | S40: 1.4345852
B41: 28277 | C41: 142.95 | D41: 13.9 | E41: 103.84 | F41: 84.294769 | G41: 100.48 | H41: 7.28 | I41: 0.66 | K41: SPX500 | L41: 0.30286726 | M41: 0.011938426 | N41: 25.369112 | O41: 1.0518766e-96 | P41: 0.27942052 | Q41: 0.326314 | R41: 0.27942052 | S41: 0.326314
B42: 28307 | C42: 144.5 | D42: 13.9 | E42: 102.86 | F42: 98.000565 | G42: 98.85 | H42: 7.33 | I42: 0.49
...

Sheet CHART GOLD

Sheet REGRESSION SILVER 1975-2024
B1: ALL DATA EXTRACTED
B3: Independent Variable:- | E3: Dependent Variable: Gold Price
B4: 1.Interest Rate
B5: 2. Inflation Rate
B6: 3. Oil Price
B7: 4. DXY
B8: 5. GPRH
C10: Y | D10: X2 | E10: X3 | F10: X6 | G10: X1 | H10: X5 | I10: X4
B11: DATE | C11: Silver Price | D11: Inflation Changes | E11: Oil Price | F11: SPX500 | G11: Interest Rate | H11: GPRHT | I11: DXY | L11: Interest Rate | M11: Inflation Changes | N11: Oil Price | O11: Oil Price | P11: GPRHT | Q11: SPX500
B12: 27395 | C12: 4.15 | D12: 0.39 | E12: 11.16 | F12: 76.98 | G12: 7.5 | H12: 83.855362 | I12: 95.61 | K12: Interest Rate | L12: 1
B13: 27426 | C13: 4.42 | D13: 0.77 | E13: 11.16 | F13: 81.59 | G13: 7.39 | H13: 112.82957 | I13: 93 | K13: Inflation Changes | L13: 0.33132365 | M13: 1
B14: 27454 | C14: 4.28 | D14: 0.38 | E14: 11.16 | F14: 83.36 | G14: 7.73 | H14: 81.504486 | I14: 94.82 | K14: Oil Price | L14: -0.57507259 | M14: -0.079022384 | N14: 1 | O14: 1
B15: 27485 | C15: 4.43 | D15: 0.38 | E15: 11.16 | F15: 87.3 | G15: 8.23 | H15: 89.517914 | I15: 95.39 | K15: DXY | L15: 0.47736574 | M15: 0.0030447475 | N15: -0.38291898 | O15: -0.38291898
B16: 27515 | C16: 4.53 | D16: 0.57 | E16: 11.16 | F16: 91.15 | G16: 8.06 | H16: 91.751518 | I16: 94.63 | K16: GPRHT | L16: 0.28471385 | M16: 0.20999041 | N16: -0.023984135 | O16: -0.023984135 | P16: 1
B17: 27546 | C17: 4.57 | D17: 0.75 | E17: 11.16 | F17: 95.19 | G17: 7.86 | H17: 104.65205 | I17: 95.86 | K17: SPX500 | L17: -0.67758122 | M17: -0.14469664 | N17: 0.60290619 | O17: 0.60290619 | P17: -0.0062193239 | Q17: 1
B18: 27576 | C18: 5 | D18: 1.12 | E18: 11.16 | F18: 88.75 | G18: 8.06 | H18: 130.41939 | I18: 101.25
B19: 27607 | C19: 4.63 | D19: 0.18 | E19: 11.16 | F19: 86.88 | G19: 8.4 | H19: 119.28921 | I19: 101.79 | K19: SUMMARY OUTPUT
B20: 27638 | C20: 4.44 | D20: 0.55 | E20: 11.16 | F20: 83.87 | G20: 8.43 | H20: 91.548004 | I20: 104.24
B21: 27668 | C21: 4.19 | D21: 0.55 | E21: 11.16 | F21: 89.04 | G21: 8.14 | H21: 95.561226 | I21: 101.61 | K21: Regression Statistics
B22: 27699 | C22: 4.23 | D22: 0.73 | E22: 11.16 | F22: 91.24 | G22: 8.05 | H22: 98.560883 | I22: 103.53 | K22: Multiple R | L22: 0.83473601
B23: 27729 | C23: 4.18 | D23: 0.36 | E23: 11.16 | F23: 90.19 | G23: 8 | H23: 83.333817 | I23: 103.51 | K23: R Square | L23: 0.69678421
B24: 27760 | C24: 4.01 | D24: 0.18 | E24: 11.16 | F24: 100.86 | G24: 7.74 | H24: 99.605568 | I24: 103.88 | K24: Adjusted R Square | L24: 0.69371626
B25: 27791 | C25: 4.16 | D25: 0.36 | E25: 12.03 | F25: 99.71 | G25: 7.79 | H25: 61.639027 | I25: 103.66 | K25: Standard Error | L25: 4.6720332
B26: 27820 | C26: 4.11 | D26: 0.18 | E26: 12.1 | F26: 102.77 | G26: 7.73 | H26: 94.420204 | I26: 105.34 | K26: Observations | L26: 600
B27: 27851 | C27: 4.43 | D27: 0.36 | E27: 12.17 | F27: 101.64 | G27: 7.56 | H27: 76.181549 | I27: 106.23
B28: 27881 | C28: 4.62 | D28: 0.71 | E28: 12.17 | F28: 100.18 | G28: 7.9 | H28: 90.447502 | I28: 107.29 | K28: ANOVA
B29: 27912 | C29: 4.83 | D29: 0.53 | E29: 12.17 | F29: 104.28 | G29: 7.86 | H29: 79.715508 | I29: 106.64 | L29: df | M29: SS | N29: MS | O29: F | P29: Significance F
B30: 27942 | C30: 4.54 | D30: 0.53 | E30: 12.17 | F30: 103.44 | G30: 7.83 | H30: 62.278923 | I30: 106.56 | K30: Regression | L30: 6 | M30: 29744.935 | N30: 4957.4891 | O30: 227.11715 | P30: 4.7236857e-150
B31: 27973 | C31: 4.11 | D31: 0.53 | E31: 12.17 | F31: 102.91 | G31: 7.77 | H31: 108.76436 | I31: 106.13 | K31: Residual | L31: 593 | M31: 12943.941 | N31: 21.827894
B32: 28004 | C32: 4.39 | D32: 0.35 | E32: 13.9 | F32: 105.24 | G32: 7.59 | H32: 76.601311 | I32: 105.5 | K32: Total | L32: 599 | M32: 42688.876
B33: 28034 | C33: 4.27 | D33: 0.52 | E33: 13.9 | F33: 102.9 | G33: 7.41 | H33: 85.47039 | I33: 105.94
B34: 28065 | C34: 4.28 | D34: 0.17 | E34: 13.9 | F34: 102.1 | G34: 7.29 | H34: 66.941399 | I34: 106.19 | L34: Coefficients | M34: Standard Error | N34: t Stat | O34: P-value | P34: Lower 95% | Q34: Upper 95% | R34: Lower 95.0% | S34: Upper 95.0%
B35: 28095 | C35: 4.36 | D35: 0.34 | E35: 13.9 | F35: 107.46 | G35: 6.87 | H35: 80.23188 | I35: 104.56 | K35: Intercept | L35: 3.6636286 | M35: 1.6207602 | N35: 2.2604383 | O35: 0.024155833 | P35: 0.48050007 | Q35: 6.8467571 | R35: 0.48050007 | S35: 6.8467571
B36: 28126 | C36: 4.45 | D36: 0.52 | E36: 13.9 | F36: 102.03 | G36: 7.21 | H36: 78.585274 | I36: 105.54 | K36: Interest Rate | L36: 0.21193204 | M36: 0.11115382 | N36: 1.9066555 | O36: 0.057048241 | P36: -0.0063709991 | Q36: 0.43023507 | R36: -0.0063709991 | S36: 0.43023507
B37: 28157 | C37: 4.73 | D37: 1.03 | E37: 13.9 | F37: 99.82 | G37: 7.39 | H37: 84.99382 | I37: 105.26 | K37: Inflation Changes | L37: 1.6351952 | M37: 0.57601186 | N37: 2.838822 | O37: 0.0046831576 | P37: 0.50392371 | Q37: 2.7664666 | R37: 0.50392371 | S37: 2.7664666
B38: 28185 | C38: 4.83 | D38: 0.68 | E38: 13.9 | F38: 98.42 | G38: 7.46 | H38: 83.106659 | I38: 105.03 | K38: Oil Price | L38: 0.19115369 | M38: 0.0093749735 | N38: 20.389784 | O38: 1.9788878e-70 | P38: 0.1727415 | Q38: 0.20956588 | R38: 0.1727415 | S38: 0.20956588
B39: 28216 | C39: 4.71 | D39: 0.84 | E39: 13.9 | F39: 98.44 | G39: 7.37 | H39: 94.549332 | I39: 104.39 | K39: DXY | L39: -0.046555369 | M39: 0.017560694 | N39: -2.6511121 | O39: 0.0082370937 | P39: -0.08104409 | Q39: -0.012066649 | R39: -0.08104409 | S39: -0.012066649
B40: 28246 | C40: 4.56 | D40: 0.5 | E40: 13.9 | F40: 96.12 | G40: 7.46 | H40: 94.379166 | I40: 104.52 | K40: GPRHT | L40: 0.00086295447 | M40: 0.0058019103 | N40: 0.14873626 | O40: 0.88181231 | P40: -0.010531838 | Q40: 0.012257747 | R40: -0.010531838 | S40: 0.012257747
B41: 28277 | C41: 4.51 | D41: 0.66 | E41: 13.9 | F41: 100.48 | G41: 7.28 | H41: 84.294769 | I41: 103.84 | K41: SPX500 | L41: 0.0020846991 | M41: 0.00025373393 | N41: 8.2160833 | O41: 1.3241921e-15 | P41: 0.0015863726 | Q41: 0.0025830256 | R41: 0.0015863726 | S41: 0.0025830256
B42: 28307 | C42: 4.52 | D42: 0.49 | E42: 13.9 | F42: 98.85 | G42: 7.33 | H42: 98.000565 | I42: 102.86
...

Sheet CHART GOLD 1975-2024

Sheet CHART SILVER 1975-2024

Sheet REGRESSION SILVER
B1: ALL DATA EXTRACTED
B3: Independent Variable:- | E3: Dependent Variable: Gold Price
B4: 1.Interest Rate
B5: 2. Inflation Rate
B6: 3. Oil Price
B7: 4. DXY
B8: 5. GPRH
C10: Y | D10: X1 | E10: X3 | F10: X4 | G10: X6 | H10: X2 | I10: X5
B11: DATE | C11: Silver Price | D11: Interest Rate | E11: Oil Price | F11: DXY | G11: SPX500 | H11: Inflation Changes | I11: GPRHT | L11: Interest Rate | M11: Inflation Changes | N11: Oil Price | O11: DXY | P11: GPRHT | Q11: SPX500
B12: 27395 | C12: 4.15 | D12: 7.5 | E12: 11.16 | F12: 95.61 | G12: 76.98 | H12: 0.39 | I12: 83.855362 | K12: Interest Rate | L12: 1
B13: 27426 | C13: 4.42 | D13: 7.39 | E13: 11.16 | F13: 93 | G13: 81.59 | H13: 0.77 | I13: 112.82957 | K13: Inflation Changes | L13: 0.33186373 | M13: 1
B14: 27454 | C14: 4.28 | D14: 7.73 | E14: 11.16 | F14: 94.82 | G14: 83.36 | H14: 0.38 | I14: 81.504486 | K14: Oil Price | L14: -0.57753328 | M14: -0.079975981 | N14: 1
B15: 27485 | C15: 4.43 | D15: 8.23 | E15: 11.16 | F15: 95.39 | G15: 87.3 | H15: 0.38 | I15: 89.517914 | K15: DXY | L15: 0.47283863 | M15: 0.0034507835 | N15: -0.37456919 | O15: 1
B16: 27515 | C16: 4.53 | D16: 8.06 | E16: 11.16 | F16: 94.63 | G16: 91.15 | H16: 0.57 | I16: 91.751518 | K16: GPRHT | L16: 0.26201117 | M16: 0.19700818 | N16: -0.0015869465 | O16: 0.16835579 | P16: 1
B17: 27546 | C17: 4.57 | D17: 7.86 | E17: 11.16 | F17: 95.86 | G17: 95.19 | H17: 0.75 | I17: 104.65205 | K17: SPX500 | L17: -0.62386929 | M17: -0.14306449 | N17: 0.57694065 | O17: -0.058942449 | P17: 0.090846169 | Q17: 1
B18: 27576 | C18: 5 | D18: 8.06 | E18: 11.16 | F18: 101.25 | G18: 88.75 | H18: 1.12 | I18: 130.41939
B19: 27607 | C19: 4.63 | D19: 8.4 | E19: 11.16 | F19: 101.79 | G19: 86.88 | H19: 0.18 | I19: 119.28921 | K19: SUMMARY OUTPUT
B20: 27638 | C20: 4.44 | D20: 8.43 | E20: 11.16 | F20: 104.24 | G20: 83.87 | H20: 0.55 | I20: 91.548004
B21: 27668 | C21: 4.19 | D21: 8.14 | E21: 11.16 | F21: 101.61 | G21: 89.04 | H21: 0.55 | I21: 95.561226 | K21: Regression Statistics
B22: 27699 | C22: 4.23 | D22: 8.05 | E22: 11.16 | F22: 103.53 | G22: 91.24 | H22: 0.73 | I22: 98.560883 | K22: Multiple R | L22: 0.83848192
B23: 27729 | C23: 4.18 | D23: 8 | E23: 11.16 | F23: 103.51 | G23: 90.19 | H23: 0.36 | I23: 83.333817 | K23: R Square | L23: 0.70305193
B24: 27760 | C24: 4.01 | D24: 7.74 | E24: 11.16 | F24: 103.88 | G24: 100.86 | H24: 0.18 | I24: 99.605568 | K24: Adjusted R Square | L24: 0.70010699
B25: 27791 | C25: 4.16 | D25: 7.79 | E25: 12.03 | F25: 103.66 | G25: 99.71 | H25: 0.36 | I25: 61.639027 | K25: Standard Error | L25: 5.1866084
B26: 27820 | C26: 4.11 | D26: 7.73 | E26: 12.1 | F26: 105.34 | G26: 102.77 | H26: 0.18 | I26: 94.420204 | K26: Observations | L26: 612
B27: 27851 | C27: 4.43 | D27: 7.56 | E27: 12.17 | F27: 106.23 | G27: 101.64 | H27: 0.36 | I27: 76.181549
B28: 27881 | C28: 4.62 | D28: 7.9 | E28: 12.17 | F28: 107.29 | G28: 100.18 | H28: 0.71 | I28: 90.447502 | K28: ANOVA
B29: 27912 | C29: 4.83 | D29: 7.86 | E29: 12.17 | F29: 106.64 | G29: 104.28 | H29: 0.53 | I29: 79.715508 | L29: df | M29: SS | N29: MS | O29: F | P29: Significance F
B30: 27942 | C30: 4.54 | D30: 7.83 | E30: 12.17 | F30: 106.56 | G30: 103.44 | H30: 0.53 | I30: 62.278923 | K30: Regression | L30: 6 | M30: 38532.679 | N30: 6422.1132 | O30: 238.73222 | P30: 7.0105317e-156 | Q30: <5%
B31: 27973 | C31: 4.11 | D31: 7.77 | E31: 12.17 | F31: 106.13 | G31: 102.91 | H31: 0.53 | I31: 108.76436 | K31: Residual | L31: 605 | M31: 16275.049 | N31: 26.900907
B32: 28004 | C32: 4.39 | D32: 7.59 | E32: 13.9 | F32: 105.5 | G32: 105.24 | H32: 0.35 | I32: 76.601311 | K32: Total | L32: 611 | M32: 54807.728
B33: 28034 | C33: 4.27 | D33: 7.41 | E33: 13.9 | F33: 105.94 | G33: 102.9 | H33: 0.52 | I33: 85.47039
B34: 28065 | C34: 4.28 | D34: 7.29 | E34: 13.9 | F34: 106.19 | G34: 102.1 | H34: 0.17 | I34: 66.941399 | L34: Coefficients | M34: Standard Error | N34: t Stat | O34: P-value | P34: Lower 95% | Q34: Upper 95% | R34: Lower 95.0% | S34: Upper 95.0%
B35: 28095 | C35: 4.36 | D35: 6.87 | E35: 13.9 | F35: 104.56 | G35: 107.46 | H35: 0.34 | I35: 80.23188 | K35: Intercept | L35: 4.8455222 | M35: 1.794759 | N35: 2.6998178 | O35: 0.0071317748 | P35: 1.3208079 | Q35: 8.3702364 | R35: 1.3208079 | S35: 8.3702364
B36: 28126 | C36: 4.45 | D36: 7.21 | E36: 13.9 | F36: 105.54 | G36: 102.03 | H36: 0.52 | I36: 78.585274 | K36: Interest Rate | L36: 0.58294452 | M36: 0.11659297 | N36: 4.9998255 | O36: 7.5263499e-07 | P36: 0.35396842 | Q36: 0.81192062 | R36: 0.35396842 | S36: 0.81192062
B37: 28157 | C37: 4.73 | D37: 7.39 | E37: 13.9 | F37: 105.26 | G37: 99.82 | H37: 1.03 | I37: 84.99382 | K37: Inflation Changes | L37: 0.72864982 | M37: 0.63282108 | N37: 1.151431 | O37: 0.25000979 | P37: -0.51414296 | Q37: 1.9714426 | R37: -0.51414296 | S37: 1.9714426
B38: 28185 | C38: 4.83 | D38: 7.46 | E38: 13.9 | F38: 105.03 | G38: 98.42 | H38: 0.68 | I38: 83.106659 | K38: Oil Price | L38: 0.17163659 | M38: 0.01020333 | N38: 16.821624 | O38: 2.2317832e-52 | P38: 0.15159834 | Q38: 0.19167483 | R38: 0.15159834 | S38: 0.19167483
B39: 28216 | C39: 4.71 | D39: 7.37 | E39: 13.9 | F39: 104.39 | G39: 98.44 | H39: 0.84 | I39: 94.549332 | K39: DXY | L39: -0.088675926 | M39: 0.018992068 | N39: -4.6691031 | O39: 3.7290887e-06 | P39: -0.12597431 | Q39: -0.051377539 | R39: -0.12597431 | S39: -0.051377539
B40: 28246 | C40: 4.56 | D40: 7.46 | E40: 13.9 | F40: 104.52 | G40: 96.12 | H40: 0.5 | I40: 94.379166 | K40: GPRHT | L40: 0.0027011894 | M40: 0.0063597243 | N40: 0.42473372 | O40: 0.67118181 | P40: -0.0097886275 | Q40: 0.015191006 | R40: -0.0097886275 | S40: 0.015191006
B41: 28277 | C41: 4.51 | D41: 7.28 | E41: 13.9 | F41: 103.84 | G41: 100.48 | H41: 0.66 | I41: 84.294769 | K41: SPX500 | L41: 0.0035326544 | M41: 0.00022963394 | N41: 15.383851 | O41: 2.5779817e-45 | P41: 0.003081678 | Q41: 0.0039836309 | R41: 0.003081678 | S41: 0.0039836309
B42: 28307 | C42: 4.52 | D42: 7.33 | E42: 13.9 | F42: 102.86 | G42: 98.85 | H42: 0.49 | I42: 98.000565 | O42: P-value <5%
...

Sheet CHART SILVER

Sheet REGRESSION GOLD TEST
B1: ALL DATA EXTRACTED
B3: Independent Variable:-
B4: 1.Interest Rate | E4: Dependent Variable: Gold Price
B5: 2. Inflation Rate
B6: 3. Oil Price
B7: 4. DXY
B8: 5. GPRH
B10: DATE | C10: GOLD (Y) | D10: INTEREST RATE (X1) | E10: OIL PRICE (X3) | F10: DXY (X4) | G10: GPRH (X5) | H10: INFLATION RATE (X2)
B11: 27395 | C11: 176.27 | D11: 7.5 | E11: 11.16 | F11: 95.61 | G11: 73.167297 | H11: 0.39 | K11: INTEREST RATE (X1) | L11: INFLATION RATE (X2) | M11: OIL PRICE (X3) | N11: DXY (X4) | O11: GPRH (X5)
B12: 27396 | C12: 179.6 | D12: 7.39 | E12: 11.16 | F12: 93 | G12: 86.054886 | H12: 0.77 | J12: INTEREST RATE (X1) | K12: 1
B13: 27397 | C13: 178.16 | D13: 7.73 | E13: 11.16 | F13: 94.82 | G13: 87.001091 | H13: 0.38 | J13: INFLATION RATE (X2) | K13: 0.33186373 | L13: 1
B14: 27398 | C14: 169.84 | D14: 8.23 | E14: 11.16 | F14: 95.39 | G14: 82.641464 | H14: 0.38 | J14: OIL PRICE (X3) | K14: -0.57753328 | L14: -0.079975981 | M14: 1
B15: 27399 | C15: 167.39 | D15: 8.06 | E15: 11.16 | F15: 94.63 | G15: 69.514923 | H15: 0.57 | J15: DXY (X4) | K15: 0.47283863 | L15: 0.0034507835 | M15: -0.37456919 | N15: 1
B16: 27400 | C16: 164.24 | D16: 7.86 | E16: 11.16 | F16: 95.86 | G16: 73.45472 | H16: 0.75 | J16: GPRH (X5) | K16: 0.16732073 | L16: 0.078176328 | M16: 0.0067537663 | N16: 0.16494152 | O16: 1
B17: 27401 | C17: 165.17 | D17: 8.06 | E17: 11.16 | F17: 101.25 | G17: 87.465973 | H17: 1.12
B18: 27402 | C18: 163 | D18: 8.4 | E18: 11.16 | F18: 101.79 | G18: 92.539864 | H18: 0.18 | J18: SUMMARY OUTPUT
B19: 27403 | C19: 144.17 | D19: 8.43 | E19: 11.16 | F19: 104.24 | G19: 69.647133 | H19: 0.55
B20: 27404 | C20: 142.79 | D20: 8.14 | E20: 11.16 | F20: 101.61 | G20: 77.191345 | H20: 0.55 | J20: Regression Statistics
B21: 27405 | C21: 142.42 | D21: 8.05 | E21: 11.16 | F21: 103.53 | G21: 71.163002 | H21: 0.73 | J21: Multiple R | K21: 0.75719759
B22: 27406 | C22: 139.3 | D22: 8 | E22: 11.16 | F22: 103.51 | G22: 79.85717 | H22: 0.36 | J22: R Square | K22: 0.5733482
B23: 27760 | C23: 131.05 | D23: 7.74 | E23: 11.16 | F23: 103.88 | G23: 82.461548 | H23: 0.18 | J23: Adjusted R Square | K23: 0.56982797
B24: 27761 | C24: 131.06 | D24: 7.79 | E24: 12.03 | F24: 103.66 | G24: 53.818283 | H24: 0.36 | J24: Standard Error | K24: 452.04463
B25: 27762 | C25: 132.76 | D25: 7.73 | E25: 12.1 | F25: 105.34 | G25: 69.601067 | H25: 0.18 | J25: Observations | K25: 612
B26: 27763 | C26: 127.94 | D26: 7.56 | E26: 12.17 | F26: 106.23 | G26: 62.143448 | H26: 0.36
B27: 27764 | C27: 126.92 | D27: 7.9 | E27: 12.17 | F27: 107.29 | G27: 67.540115 | H27: 0.71 | J27: ANOVA
B28: 27765 | C28: 125.71 | D28: 7.86 | E28: 12.17 | F28: 106.64 | G28: 68.002213 | H28: 0.53 | K28: df | L28: SS | M28: MS | N28: F | O28: Significance F
B29: 27766 | C29: 117.73 | D29: 7.83 | E29: 12.17 | F29: 106.56 | G29: 78.572227 | H29: 0.53 | J29: Regression | K29: 5 | L29: 1.6641027e+08 | M29: 33282054 | N29: 162.8724 | O29: 1.421435e-109
B30: 27767 | C30: 109.93 | D30: 7.77 | E30: 12.17 | F30: 106.13 | G30: 91.084259 | H30: 0.53 | J30: Residual | K30: 606 | L30: 1.2383268e+08 | M30: 204344.35
B31: 27768 | C31: 114.15 | D31: 7.59 | E31: 13.9 | F31: 105.5 | G31: 69.401604 | H31: 0.35 | J31: Total | K31: 611 | L31: 2.9024295e+08
B32: 27769 | C32: 116.15 | D32: 7.41 | E32: 13.9 | F32: 105.94 | G32: 67.357544 | H32: 0.52
B33: 27770 | C33: 130.46 | D33: 7.29 | E33: 13.9 | F33: 106.19 | G33: 58.609882 | H33: 0.17 | K33: Coefficients | L33: Standard Error | M33: t Stat | N33: P-value | O33: Lower 95% | P33: Upper 95% | Q33: Lower 95.0% | R33: Upper 95.0%
B34: 27771 | C34: 133.93 | D34: 6.87 | E34: 13.9 | F34: 104.56 | G34: 62.196987 | H34: 0.34 | J34: Intercept | K34: -398.18601 | L34: 152.32456 | M34: -2.6140631 | N34: 0.009169622 | O34: -697.33413 | P34: -99.037898 | Q34: -697.33413 | R34: -99.037898
B35: 28126 | C35: 132.26 | D35: 7.21 | E35: 13.9 | F35: 105.54 | G35: 55.85688 | H35: 0.52 | J35: INTEREST RATE (X1) | K35: -79.599186 | L35: 8.0615818 | M35: -9.8738917 | N35: 2.0169156e-21 | O35: -95.431216 | P35: -63.767156 | Q35: -95.431216 | R35: -63.767156
B36: 28127 | C36: 136.24 | D36: 7.39 | E36: 13.9 | F36: 105.26 | G36: 64.896774 | H36: 1.03 | J36: INFLATION RATE (X2) | K36: 52.066413 | L36: 54.574683 | M36: 0.95403967 | N36: 0.34044395 | O36: -55.11206 | P36: 159.24489 | Q36: -55.11206 | R36: 159.24489
B37: 28128 | C37: 148.23 | D37: 7.46 | E37: 13.9 | F37: 105.03 | G37: 61.689423 | H37: 0.68 | J37: OIL PRICE (X3) | K37: 13.700651 | L37: 0.81935265 | M37: 16.721312 | N37: 6.8424608e-52 | O37: 12.091536 | P37: 15.309767 | Q37: 12.091536 | R37: 15.309767
B38: 28129 | C38: 149.17 | D38: 7.37 | E38: 13.9 | F38: 104.39 | G38: 78.984024 | H38: 0.84 | J38: DXY (X4) | K38: 9.3851252 | L38: 1.5026609 | M38: 6.2456709 | N38: 7.9461917e-10 | O38: 6.4340701 | P38: 12.33618 | Q38: 6.4340701 | R38: 12.33618
B39: 28130 | C39: 146.61 | D39: 7.46 | E39: 13.9 | F39: 104.52 | G39: 74.192535 | H39: 0.5 | J39: GPRH (X5) | K39: 1.7356917 | L39: 0.63118655 | M39: 2.749887 | N39: 0.0061394998 | O39: 0.49611305 | P39: 2.9752703 | Q39: 0.49611305 | R39: 2.9752703
B40: 28131 | C40: 140.78 | D40: 7.28 | E40: 13.9 | F40: 103.84 | G40: 67.767151 | H40: 0.66
B41: 28132 | C41: 143.39 | D41: 7.33 | E41: 13.9 | F41: 102.86 | G41: 77.617676 | H41: 0.49
B42: 28133 | C42: 144.94 | D42: 7.4 | E42: 14.85 | F42: 103.64 | G42: 72.078178 | H42: 0.33 | J42: SUMMARY OUTPUT
...

Sheet REGRESSION SILVER TEST
B1: ALL DATA EXTRACTED
B3: Independent Variable:- | E3: Dependent Variable: Silver Price
B4: 1.Interest Rate
B5: 2. Inflation Rate
B6: 3. Oil Price
B7: 4. DXY
B8: 5. GPRH
B10: DATE | C10: SILVER (Y) | D10: INTEREST RATE (X1) | E10: INFLATION RATE (X2) | F10: OIL PRICE (X3) | G10: DXY (X4) | H10: GPRH (X5)
B11: 27395 | C11: 4.15 | D11: 7.5 | E11: 0.39 | F11: 11.16 | G11: 95.61 | H11: 73.167297 | K11: INTEREST RATE (X1) | L11: INFLATION RATE (X2) | M11: OIL PRICE (X3) | N11: DXY (X4) | O11: GPRH (X5)
B12: 27396 | C12: 4.42 | D12: 7.39 | E12: 0.77 | F12: 11.16 | G12: 93 | H12: 86.054886 | J12: INTEREST RATE (X1)
B13: 27397 | C13: 4.28 | D13: 7.73 | E13: 0.38 | F13: 11.16 | G13: 94.82 | H13: 87.001091 | J13: INFLATION RATE (X2) | K13: 0.33186373
B14: 27398 | C14: 4.43 | D14: 8.23 | E14: 0.38 | F14: 11.16 | G14: 95.39 | H14: 82.641464 | J14: OIL PRICE (X3) | K14: -0.57753328 | L14: -0.079975981
B15: 27399 | C15: 4.53 | D15: 8.06 | E15: 0.57 | F15: 11.16 | G15: 94.63 | H15: 69.514923 | J15: DXY (X4) | K15: 0.47283863 | L15: 0.0034507835 | M15: -0.37456919
B16: 27400 | C16: 4.57 | D16: 7.86 | E16: 0.75 | F16: 11.16 | G16: 95.86 | H16: 73.45472 | J16: GPRH (X5) | K16: 0.16732073 | L16: 0.078176328 | M16: 0.0067537663 | N16: 0.16494152
B17: 27401 | C17: 5 | D17: 8.06 | E17: 1.12 | F17: 11.16 | G17: 101.25 | H17: 87.465973
B18: 27402 | C18: 4.63 | D18: 8.4 | E18: 0.18 | F18: 11.16 | G18: 101.79 | H18: 92.539864 | J18: SUMMARY OUTPUT
B19: 27403 | C19: 4.44 | D19: 8.43 | E19: 0.55 | F19: 11.16 | G19: 104.24 | H19: 69.647133
B20: 27404 | C20: 4.19 | D20: 8.14 | E20: 0.55 | F20: 11.16 | G20: 101.61 | H20: 77.191345 | J20: Regression Statistics
B21: 27405 | C21: 4.23 | D21: 8.05 | E21: 0.73 | F21: 11.16 | G21: 103.53 | H21: 71.163002 | J21: Multiple R | K21: 0.75876289
B22: 27406 | C22: 4.18 | D22: 8 | E22: 0.36 | F22: 11.16 | G22: 103.51 | H22: 79.85717 | J22: R Square | K22: 0.57572112
B23: 27760 | C23: 4.01 | D23: 7.74 | E23: 0.18 | F23: 11.16 | G23: 103.88 | H23: 82.461548 | J23: Adjusted R Square | K23: 0.57222047
B24: 27761 | C24: 4.16 | D24: 7.79 | E24: 0.36 | F24: 12.03 | G24: 103.66 | H24: 53.818283 | J24: Standard Error | K24: 6.1945575
B25: 27762 | C25: 4.11 | D25: 7.73 | E25: 0.18 | F25: 12.1 | G25: 105.34 | H25: 69.601067 | J25: Observations | K25: 612
B26: 27763 | C26: 4.43 | D26: 7.56 | E26: 0.36 | F26: 12.17 | G26: 106.23 | H26: 62.143448
B27: 27764 | C27: 4.62 | D27: 7.9 | E27: 0.71 | F27: 12.17 | G27: 107.29 | H27: 67.540115 | J27: ANOVA
B28: 27765 | C28: 4.83 | D28: 7.86 | E28: 0.53 | F28: 12.17 | G28: 106.64 | H28: 68.002213 | K28: df | L28: SS | M28: MS | N28: F | O28: Significance F
B29: 27766 | C29: 4.54 | D29: 7.83 | E29: 0.53 | F29: 12.17 | G29: 106.56 | H29: 78.572227 | J29: Regression | K29: 5 | L29: 31553.967 | M29: 6310.7933 | N29: 164.46117 | O29: 2.6392638e-110
B30: 27767 | C30: 4.11 | D30: 7.77 | E30: 0.53 | F30: 12.17 | G30: 106.13 | H30: 91.084259 | J30: Residual | K30: 606 | L30: 23253.761 | M30: 38.372543
B31: 27768 | C31: 4.39 | D31: 7.59 | E31: 0.35 | F31: 13.9 | G31: 105.5 | H31: 69.401604 | J31: Total | K31: 611 | L31: 54807.728
B32: 27769 | C32: 4.27 | D32: 7.41 | E32: 0.52 | F32: 13.9 | G32: 105.94 | H32: 67.357544
B33: 27770 | C33: 4.28 | D33: 7.29 | E33: 0.17 | F33: 13.9 | G33: 106.19 | H33: 58.609882 | K33: Coefficients | L33: Standard Error | M33: t Stat | N33: P-value | O33: Lower 95% | P33: Upper 95% | Q33: Lower 95.0% | R33: Upper 95.0%
B34: 27771 | C34: 4.36 | D34: 6.87 | E34: 0.34 | F34: 13.9 | G34: 104.56 | H34: 62.196987 | J34: Intercept | K34: -0.87730537 | L34: 2.0873674 | M34: -0.42029274 | N34: 0.6744206 | O34: -4.9766577 | P34: 3.2220469 | Q34: -4.9766577 | R34: 3.2220469
B35: 28126 | C35: 4.45 | D35: 7.21 | E35: 0.52 | F35: 13.9 | G35: 105.54 | H35: 55.85688 | J35: INTEREST RATE (X1) | K35: -0.39204857 | L35: 0.11047124 | M35: -3.5488745 | N35: 0.00041683947 | O35: -0.60900153 | P35: -0.17509561 | Q35: -0.60900153 | R35: -0.17509561
B36: 28127 | C36: 4.73 | D36: 7.39 | E36: 1.03 | F36: 13.9 | G36: 105.26 | H36: 64.896774 | J36: INFLATION RATE (X2) | K36: 1.9902031 | L36: 0.74785981 | M36: 2.6611982 | N36: 0.0079926855 | O36: 0.5214915 | P36: 3.4589148 | Q36: 0.5214915 | R36: 3.4589148
B37: 28128 | C37: 4.83 | D37: 7.46 | E37: 0.68 | F37: 13.9 | G37: 105.03 | H37: 61.689423 | J37: OIL PRICE (X3) | K37: 0.23707149 | L37: 0.011227934 | M37: 21.114436 | N37: 1.3708113e-74 | O37: 0.2150211 | P37: 0.25912187 | Q37: 0.2150211 | R37: 0.25912187
B38: 28129 | C38: 4.71 | D38: 7.37 | E38: 0.84 | F38: 13.9 | G38: 104.39 | H38: 78.984024 | J38: DXY (X4) | K38: 0.041271856 | L38: 0.020591593 | M38: 2.0043061 | N38: 0.045481754 | O38: 0.0008323083 | P38: 0.081711405 | Q38: 0.0008323083 | R38: 0.081711405
B39: 28130 | C39: 4.56 | D39: 7.46 | E39: 0.5 | F39: 13.9 | G39: 104.52 | H39: 74.192535 | J39: GPRH (X5) | K39: 0.008281865 | L39: 0.0086494145 | M39: 0.95750585 | N39: 0.33869382 | O39: -0.0087046018 | P39: 0.025268332 | Q39: -0.0087046018 | R39: 0.025268332
B40: 28131 | C40: 4.51 | D40: 7.28 | E40: 0.66 | F40: 13.9 | G40: 103.84 | H40: 67.767151
B41: 28132 | C41: 4.52 | D41: 7.33 | E41: 0.49 | F41: 13.9 | G41: 102.86 | H41: 77.617676
B42: 28133 | C42: 4.45 | D42: 7.4 | E42: 0.33 | F42: 14.85 | G42: 103.64 | H42: 72.078178 | J42: SUMMARY OUTPUT
...
